<?xml version="1.0"?>
<robot name="franka_panda">
  <link name="panda_link0">
    <visual><geometry><mesh filename="meshes/link0.stl"/></geometry></visual>
    <collision><geometry><mesh filename="meshes/link0.stl"/></geometry></collision>
  </link>

  <link name="panda_link1">
    <visual><geometry><mesh filename="meshes/link1.stl"/></geometry></visual>
    <collision><geometry><mesh filename="meshes/link1.stl"/></geometry></collision>
  </link>

  <joint name="panda_joint1" type="revolute">
    <parent link="panda_link0"/>
    <child link="panda_link1"/>
    <origin xyz="0 0 0.333" rpy="0 0 0"/>
    <axis xyz="0 0 1"/>
    <limit lower="-2.8973" upper="2.8973" effort="87" velocity="2.175"/>
  </joint>

  <link name="panda_link2">
    <visual><geometry><mesh filename="meshes/link2.stl"/></geometry></visual>
    <collision><geometry><mesh filename="meshes/link2.stl"/></geometry></collision>
  </link>

  <joint name="panda_joint2" type="revolute">
    <parent link="panda_link1"/>
    <child link="panda_link2"/>
    <origin xyz="0 0 0" rpy="-1.57079632679 0 0"/>
    <axis xyz="0 0 1"/>
    <limit lower="-1.7628" upper="1.7628" effort="87" velocity="2.175"/>
  </joint>

  <link name="panda_link3">
    <visual><geometry><mesh filename="meshes/link3.stl"/></geometry></visual>
    <collision><geometry><mesh filename="meshes/link3.stl"/></geometry></collision>
  </link>

  <joint name="panda_joint3" type="revolute">
    <parent link="panda_link2"/>
    <child link="panda_link3"/>
    <origin xyz="0 -0.316 0" rpy="1.57079632679 0 0"/>
    <axis xyz="0 0 1"/>
    <limit lower="-2.8973" upper="2.8973" effort="87" velocity="2.175"/>
  </joint>

  <link name="panda_link4">
    <visual><geometry><mesh filename="meshes/link4.stl"/></geometry></visual>
    <collision><geometry><mesh filename="meshes/link4.stl"/></geometry></collision>
  </link>

  <joint name="panda_joint4" type="revolute">
    <parent link="panda_link3"/>
    <child link="panda_link4"/>
    <origin xyz="0.0825 0 0" rpy="1.57079632679 0 0"/>
    <axis xyz="0 0 1"/>
    <limit lower="-3.0718" upper="-0.0698" effort="87" velocity="2.175"/>
  </joint>

  <link name="panda_link5">
    <visual><geometry><mesh filename="meshes/link5_0.obj"/></geometry></visual>
    <collision><geometry><mesh filename="meshes/link5_collision_0.obj"/></geometry></collision>
  </link>

  <joint name="panda_joint5" type="revolute">
    <parent link="panda_link4"/>
    <child link="panda_link5"/>
    <origin xyz="-0.0825 0.384 0" rpy="-1.57079632679 0 0"/>
    <axis xyz="0 0 1"/>
    <limit lower="-2.8973" upper="2.8973" effort="12" velocity="2.61"/>
  </joint>

  <link name="panda_link6">
    <visual><geometry><mesh filename="meshes/link6.stl"/></geometry></visual>
    <collision><geometry><mesh filename="meshes/link6.stl"/></geometry></collision>
  </link>

  <joint name="panda_joint6" type="revolute">
    <parent link="panda_link5"/>
    <child link="panda_link6"/>
    <origin xyz="0 0 0" rpy="1.57079632679 0 0"/>
    <axis xyz="0 0 1"/>
    <limit lower="-0.0175" upper="3.7525" effort="12" velocity="2.61"/>
  </joint>

  <link name="panda_link7">
    <visual><geometry><mesh filename="meshes/link7.stl"/></geometry></visual>
    <collision><geometry><mesh filename="meshes/link7.stl"/></geometry></collision>
  </link>

  <joint name="panda_joint7" type="revolute">
    <parent link="panda_link6"/>
    <child link="panda_link7"/>
    <origin xyz="0.088 0 0" rpy="1.57079632679 0 0"/>
    <axis xyz="0 0 1"/>
    <limit lower="-2.8973" upper="2.8973" effort="12" velocity="2.61"/>
  </joint>

  <link name="panda_hand">
    <visual><geometry><mesh filename="meshes/hand.stl"/></geometry></visual>
    <collision><geometry><mesh filename="meshes/hand.stl"/></geometry></collision>
  </link>

  <joint name="panda_hand_joint" type="fixed">
    <parent link="panda_link7"/>
    <child link="panda_hand"/>
    <origin xyz="0 0 0.107" rpy="0 0 -0.78539816339"/>
  </joint>

  <link name="panda_leftfinger">
    <visual><geometry><mesh filename="meshes/finger_0.obj"/></geometry></visual>
    <collision><geometry><mesh filename="meshes/finger_0.obj"/></geometry></collision>
  </link>

  <joint name="panda_finger_joint1" type="prismatic">
    <parent link="panda_hand"/>
    <child link="panda_leftfinger"/>
    <origin xyz="0 0 0.0584" rpy="0 0 0"/>
    <axis xyz="0 1 0"/>
    <limit lower="0.0" upper="0.04" effort="20" velocity="0.2"/>
  </joint>

  <link name="panda_rightfinger">
    <visual><geometry><mesh filename="meshes/finger_0.obj"/></geometry></visual>
    <collision><geometry><mesh filename="meshes/finger_0.obj"/></geometry></collision>
  </link>

  <joint name="panda_finger_joint2" type="prismatic">
    <parent link="panda_hand"/>
    <child link="panda_rightfinger"/>
    <origin xyz="0 0 0.0584" rpy="0 0 3.14159265359"/>
    <axis xyz="0 -1 0"/>
    <limit lower="0.0" upper="0.04" effort="20" velocity="0.2"/>
  </joint>
</robot>
